Workbook

Sheet INICIO
B2: SISTEMA DE GESTIÓN
B4: Panel principal • Resumen y acceso rápido
B6: VENTAS | E6: COMPRAS | H6: EFECTIVO | K6: TARJETAS
B7: =SUM(VENTAS!A:A) | E7: =SUM(Compras!A:A) | H7: =SUM('Base de Datos Efectivo'!A:A) | K7: =SUM('Base de Datos Tarjetas'!A:A)
B11: ACCESO RÁPIDO
B13: VENTAS | E13: COMPRAS | H13: EFECTIVO | K13: TARJETAS
B16: BILLETERAS | E16: INFORMES | H16: Usá los botones para navegar por el sistema. Las hojas de base de datos quedan como soporte interno.

Sheet VENTAS
A1: COBRO TARJETAS | G1: Ventas Diarias | H1: =TODAY() | I1: =SUMIF('Base de Datos Tarjetas'!A:A,TODAY(),'Base de Datos Tarjetas'!C:C) +SUMIF('Base de Datos Billeteras Virtua'!A:A,TODAY(),'Base de Datos Billeteras Virtua'!C:C) +SUMIF('Base de Datos Efectivo'!A:A,TODAY(),'Base de Datos Efectivo'!C:C)
A3: Fecha | B3: Tarjeta | C3: Monto | D3: Accion | G3: COMPRAS MENSUALES | I3: VENTAS MENSUALES
G4: =SUMIFS(Compras!C:C,Compras!A:A,">="&H6,Compras!A:A,"<="&I6) | I4: =G9
A6: COBRO BILLETERAS VIRTUALES | G6: Ventas Mensuales | H6: 46235 | I6: 46264
A8: Fecha | B8: Medio | C8: Monto | D8: Accion | G8: Ventas Tarjeta | H8: Ventas Bille. Virt | I8: Ventas Efectivo
G9: =SUMIFS('Base de Datos Tarjetas'!C:C,'Base de Datos Tarjetas'!A:A,">="&H6,'Base de Datos Tarjetas'!A:A,"<="&I6) | H9: =SUMIFS('Base de Datos Billeteras Virtua'!C:C,'Base de Datos Billeteras Virtua'!A:A,">="&H6,'Base de Datos Billeteras Virtua'!A:A,"<="&I6) | I9: =SUMIFS('Base de Datos Efectivo'!C:C,'Base de Datos Efectivo'!A:A,">="&H6,'Base de Datos Efectivo'!A:A,"<="&I6)
A11: COBRO EFECTIVO | G11: Tope Billeteras
A13: Fecha | B13: Medio | C13: Monto | D13: Accion | G13: Personal Pay | H13: Mercado Pago | I13: Naranja
G14: =SUMIFS('Base de Datos Billeteras Virtua'!C:C,'Base de Datos Billeteras Virtua'!A:A,">="&$H$6,'Base de Datos Billeteras Virtua'!A:A,"<="&$I$6,'Base de Datos Billeteras Virtua'!B:B,"Personal Pay") | H14: =SUMIFS('Base de Datos Billeteras Virtua'!C:C,'Base de Datos Billeteras Virtua'!A:A,">="&$H$6,'Base de Datos Billeteras Virtua'!A:A,"<="&$I$6,'Base de Datos Billeteras Virtua'!B:B,"Mercado Pago") | I14: =SUMIFS('Base de Datos Billeteras Virtua'!C:C,'Base de Datos Billeteras Virtua'!A:A,">="&$H$6,'Base de Datos Billeteras Virtua'!A:A,"<="&$I$6,'Base de Datos Billeteras Virtua'!B:B,"Naranja")
G15: Cantidad de Operaciones | H15: Cantidad de Operaciones | I15: Cantidad de Operaciones
G16: =COUNTIFS('Base de Datos Billeteras Virtua'!A:A,">="&$H$6,'Base de Datos Billeteras Virtua'!A:A,"<="&$I$6,'Base de Datos Billeteras Virtua'!B:B,"Personal Pay") | H16: =COUNTIFS('Base de Datos Billeteras Virtua'!A:A,">="&$H$6,'Base de Datos Billeteras Virtua'!A:A,"<="&$I$6,'Base de Datos Billeteras Virtua'!B:B,"Mercado Pago") | I16: =COUNTIFS('Base de Datos Billeteras Virtua'!A:A,">="&$H$6,'Base de Datos Billeteras Virtua'!A:A,"<="&$I$6,'Base de Datos Billeteras Virtua'!B:B,"Naranja")
G18: FACUNDO
G19: Personal Pay | H19: Mercado Pago | I19: Brubank
G20: =SUMIFS('Base de Datos Billeteras Virtua'!C:C,'Base de Datos Billeteras Virtua'!A:A,">="&$H$6,'Base de Datos Billeteras Virtua'!A:A,"<="&$I$6,'Base de Datos Billeteras Virtua'!B:B,"Personal Pay - Facundo") | H20: =SUMIFS('Base de Datos Billeteras Virtua'!C:C,'Base de Datos Billeteras Virtua'!A:A,">="&$H$6,'Base de Datos Billeteras Virtua'!A:A,"<="&$I$6,'Base de Datos Billeteras Virtua'!B:B,"Mercado Pago - Facundo") | I20: =SUMIFS('Base de Datos Billeteras Virtua'!C:C,'Base de Datos Billeteras Virtua'!A:A,">="&$H$6,'Base de Datos Billeteras Virtua'!A:A,"<="&$I$6,'Base de Datos Billeteras Virtua'!B:B,"Brubank - Facundo")
G21: Cantidad de Operaciones | H21: Cantidad de Operaciones | I21: Cantidad de Operaciones
G22: =COUNTIFS('Base de Datos Billeteras Virtua'!A:A,">="&$H$6,'Base de Datos Billeteras Virtua'!A:A,"<="&$I$6,'Base de Datos Billeteras Virtua'!B:B,"Personal Pay - Facundo") | H22: =COUNTIFS('Base de Datos Billeteras Virtua'!A:A,">="&$H$6,'Base de Datos Billeteras Virtua'!A:A,"<="&$I$6,'Base de Datos Billeteras Virtua'!B:B,"Mercado Pago - Facundo") | I22: =COUNTIFS('Base de Datos Billeteras Virtua'!A:A,">="&$H$6,'Base de Datos Billeteras Virtua'!A:A,"<="&$I$6,'Base de Datos Billeteras Virtua'!B:B,"Brubank - Facundo")
A24: COMPRAS
A26: Fecha | B26: Medio | C26: Monto | D26: CUIT | E26: TIPO DE FACTURA | F26: Accion | G26: Facturacion diaria | I26: =SUMIF('Base de Datos Tarjetas'!A:A,TODAY(),'Base de Datos Tarjetas'!C:C)
A27: 46224 | H27: Resumen Periodo | I27: =SUM(G9:I9)

Sheet Compras
A1: Fecha | B1: Medio | C1: Monto | D1: CUIT | E1: TIPO DE FACTURA | F1: Registro Movimiento
A2: 45947 | B2: Transferencia | C2: 600329.4 | D2: 20170517564 | E2: A | F2: 45955.83
A3: 45947 | B3: Transferencia | C3: 300000 | D3: 20/25319878/3 | E3: C | F3: 45958.939
A4: 45947 | B4: Efectivo | C4: 849420 | D4: 23452554119 | E4: A | F4: 45967.821
A5: 45947 | B5: Efectivo | C5: 1573000 | D5: 234525544119 | E5: A | F5: 45967.823
A6: 46050 | B6: Transferencia | C6: 229500 | D6: 20253198789 | E6: C | F6: 46050.518
A7: 46056 | B7: Transferencia | C7: 282000 | D7: 20-25319878-9 | E7: C | F7: 46066.911
A8: 46056 | B8: Transferencia | C8: 238000 | D8: 20-25319878-9 | E8: C | F8: 46066.912
A9: 46056 | B9: Transferencia | C9: 214510 | D9: 20-25319878-9 | E9: C | F9: 46066.912
A10: 46097 | B10: Transferencia | C10: 214443.46 | D10: 30715674566 | E10: A | F10: 46102.912
A11: 46097 | B11: Transferencia | C11: 400000 | D11: 33714473889 | E11: A | F11: 46157.463
A12: 46164 | B12: Efectivo | C12: 156000 | D12: 20/25319878/9 | E12: C | F12: 46164.908
A13: 46164 | B13: Efectivo | C13: 193100 | D13: 20/25319878/9 | E13: C | F13: 46164.909
A14: 46189 | B14: Efectivo | C14: 205500 | D14: 20/25319878/9 | E14: C | F14: 46189.907
A15: 46189 | B15: Efectivo | C15: 1715000 | D15: 20428208405 | E15: C | F15: 46189.91
A16: 46223 | B16: Transferencia | C16: 320000 | D16: 20274370867 | E16: C | F16: 46223.502
A17: 46224 | B17: Transferencia | C17: 183518.28 | D17: 30715674536 | E17: A | F17: 46224.784
A18: 46224 | B18: Transferencia | C18: 1080000 | D18: 20428208405 | E18: C | F18: 46224.788
A19: 46224 | B19: Transferencia | C19: 120000 | D19: 20253150789 | E19: C | F19: 46224.863
A20: 46224 | B20: Transferencia | C20: 120200 | D20: 20253198789 | E20: C | F20: 46238.494

Sheet Base de Datos Billeteras Virtua
A1: Fecha | B1: Medio de Pago | C1: Monto | G1: Billeteras V | H1: =SUM(C2:C515)
A2: 45943 | B2: Personal Pay | C2: 16000 | G2: Efectivo | H2: =SUM('Base de Datos Efectivo'!C2:C79)
A3: 45943 | B3: Personal Pay | C3: 21000 | G3: Tarjetas | H3: =SUM('Base de Datos Tarjetas'!C2:C300)
A4: 45943 | B4: Personal Pay | C4: 17000
A5: 45943 | B5: Personal Pay | C5: 5000 | H5: =SUM(H1:H3)
A6: 45943 | B6: Personal Pay | C6: 13500
A7: 45943 | B7: Personal Pay | C7: 10000
A8: 45943 | B8: Personal Pay | C8: 10000
A9: 45943 | B9: Personal Pay | C9: 6800
A10: 45943 | B10: Personal Pay | C10: 2800
A11: 45944 | B11: Personal Pay | C11: 175500
A12: 45944 | B12: Personal Pay | C12: 14980
A13: 45945 | B13: Personal Pay | C13: 58500
A14: 10/15/0825 | B14: Personal Pay | C14: 68800
A15: 45946 | B15: Personal Pay | C15: 75800
A16: 45946 | B16: Personal Pay | C16: 11000
A17: 45946 | B17: Personal Pay | C17: 25000
A18: 45946 | B18: Personal Pay | C18: 42000
A19: 45946 | B19: Personal Pay | C19: 25000
A20: 45946 | B20: Personal Pay | C20: 15000
A21: 45952 | B21: Mercado Pago | C21: 5500
A22: 45952 | B22: Personal Pay | C22: 75500
A23: 45952 | B23: Personal Pay | C23: 31400
A24: 45954 | B24: Personal Pay | C24: 18500
A25: 45954 | B25: Personal Pay | C25: 4000
A26: 45954 | B26: Personal Pay | C26: 27000
... A330: 46057 | B330: Naranja | C330: 38000
A331: 05/02/ | B331: Naranja | C331: 52500
A332: 46058 | B332: Naranja | C332: 52500
A333: 46059 | B333: Naranja | C333: 60000
A334: 46059 | B334: Naranja | C334: 44000
A335: 46059 | B335: Naranja | C335: 15000
A336: 46060 | B336: Naranja | C336: 350000
A337: 46060 | B337: Naranja | C337: 66000
A338: 46060 | B338: Naranja | C338: 25000
A339: 46060 | B339: Mercado Pago | C339: 10500
A340: 46060 | B340: Mercado Pago | C340: 28000
A341: 46060 | B341: Mercado Pago | C341: 12500
A342: 46060 | B342: Mercado Pago | C342: 72000
A343: 46060 | B343: Mercado Pago | C343: 24000
...

Sheet Base de Datos Efectivo
A1: Fecha | B1: Medio de Pago | C1: Monto
A2: 45920 | B2: EFECTIVO | C2: 15000
A3: 45929 | B3: Efectivo | C3: 12000
A4: 45943 | B4: Efectivo | C4: 51800
A5: 45945 | B5: Efectivo | C5: 27000
A6: 45947 | B6: Efectivo | C6: 25000
A7: 45947 | B7: Efectivo | C7: 75000
A8: 10/22/0825 | B8: Efectivo | C8: 90000
A9: 45954 | B9: Efectivo | C9: 30000
A10: 45954 | B10: Efectivo | C10: 20000
A11: 45954 | B11: Efectivo | C11: 33500
A12: 45954 | B12: Efectivo | C12: 59900
A13: 45955 | B13: Efectivo | C13: 60000
A14: 45958 | B14: Efectivo | C14: 20000
A15: 45960 | B15: GO Cuota | C15: 70230
A16: 45961 | B16: Efectivo | C16: 30000
A17: 45961 | B17: Efectivo | C17: 40000
A18: 45965 | B18: Efectivo | C18: 20000
A19: 45965 | B19: GO Cuota | C19: 185500
A20: 45965 | B20: GO Cuota | C20: 16100
... A137: 46256 | B137: GO Cuota | C137: 56400

Sheet Base de Datos Tarjetas
A1: Fecha | B1: Medio de Pago | C1: Monto | F1: Total a Facturar | G1: =SUMIF('Base de Datos Tarjetas'!A:A,G4,'Base de Datos Tarjetas'!C:C) | I1: =TODAY()
A2: 13/1025 | B2: VISA DEBITO | C2: 6500
A3: 45943 | B3: DATA | C3: 14380
A4: 45945 | B4: NARANJA | C4: 57500
A5: 45945 | B5: VISA CREDITO | C5: 12000
A6: 45946 | B6: VISA CREDITO | C6: 14000
A7: 45947 | B7: VISA CREDITO | C7: 10000
A8: 45947 | B8: NARANJA | C8: 62680
A9: 45947 | B9: NARANJA | C9: 151800
A10: 45947 | B10: NARANJA | C10: 73100
A11: 45947 | B11: VISA CREDITO | C11: 103000
A12: 45948 | B12: NARANJA | C12: 39680
A13: 45948 | B13: NARANJA | C13: 110980
A14: 45948 | B14: VISA CREDITO | C14: 10000
... A435: 46202 | B435: NARANJA | C435: 42320
A436: 26/6/26. | B436: NARANJA | C436: 42320
A437: 46202 | B437: NARANJA | C437: 42320
A438: 46204 | B438: NARANJA | C438: 67850
A439: 46205 | B439: DATA | C439: 41980
A440: 46205 | B440: VISA DEBITO | C440: 18000
A441: 46207 | B441: VISA CREDITO | C441: 7500
A442: 46207 | B442: NARANJA | C442: 51750
A443: 46207 | B443: FIEL | C443: 37950
A444: 46207 | B444: VISA DEBITO | C444: 43000
A445: 46207 | B445: VISA CREDITO | C445: 120000
A446: 46207 | B446: VISA CREDITO | C446: 142800
A447: 46209 | B447: DATA | C447: 56930
A448: 46209 | B448: NARANJA | C448: 59000
... A523: 46257 | B523: DATA | C523: 77050

Sheet Informe 2026
A1: Ventas Totales | B1: Efectivo | C1: Billeteras V. | D1: Tarjetas
A2: Precio Final | B2: =SUM('Base de Datos Efectivo'!C49:C10000) | C2: =SUM('Base de Datos Billeteras Virtua'!C249:C10120) | D2: =SUM('Base de Datos Tarjetas'!C176:C10000)
A3: Costo | B3: =B2*0.7 | C3: =C2*0.7 | D3: =D2*0.7
A4: Rentabilidad | B4: =B2-B3 | C4: =C2-C3 | D4: =D2-D3
A5: Estimado Facturacion al 042026
A7: Compras
A8: Facturado | B8: =SUM(Compras!C6:C1001)
A10: S/F | B10: =D3-B8 | C10: =B10*0.025
